Workbook

Sheet Decomposition
A1: SN ID | B1: Stakeholder requirement | C1: SLR ID | D1: System requirement (the NAS shall) | E1: HLR ID | F1: Sub-system HLR (constituent system shall) | G1: Objectives Addressed | H1: Review notes
A2: Stakeholder: Airline
A3: SN-AIR-01 | B3: The NAS shall provide a means for the airline to plan and fly each flight on the route, altitude and speed it chooses. | C3: SLR-PLN-01 | D3: The NAS shall produce for each scheduled flight a flight plan that states its route, cruise altitude, cruise speed and fuel load. (also answers SN-CRW-02) | E3: HLR-OPS-01 | F3: Flight operations shall plan each flight's route, cruise altitude, cruise speed and fuel load from a model of the performance of the aircraft assigned to it, with the fuel reserve the operating rules require. (also comes from SLR-PLN-02, SLR-PLN-04) | G3: {=IF(A3="","",_xlfn.TEXTJOIN(", ",TRUE,_xlfn._xlws.FILTER(Objectives!B$2:B$1000,ISNUMBER(SEARCH(A3,Objectives!D$2:D$1000)),"")))} -> Fuel cost, Crew cost, Maintenance, Delay cost, Revenue, Ticket price, Schedule convenience, Comfort, Operational flexibility, CO2, NOx, Contrail/climate effects, Noise, Local air quality
C4: SLR-PLN-02 | D4: The NAS shall compute each flight plan from the performance of the aircraft assigned to the flight. | E4: HLR-OPS-01 | F4: Flight operations shall plan each flight's route, cruise altitude, cruise speed and fuel load from a model of the performance of the aircraft assigned to it, with the fuel reserve the operating rules require. (also comes from SLR-PLN-01, SLR-PLN-04) | G4: {=IF(A4="","",_xlfn.TEXTJOIN(", ",TRUE,_xlfn._xlws.FILTER(Objectives!B$2:B$1000,ISNUMBER(SEARCH(A4,Objectives!D$2:D$1000)),"")))}
C5: SLR-CLR-09 | D5: The NAS shall answer each flight crew request for a route, altitude or speed change with an approval, an amended clearance or a refusal. (also answers SN-CRW-04, SN-PAX-03) | E5: HLR-CRW-03 | F5: The flight crew shall ask air traffic control for a change of route, altitude or speed when the crew deems it beneficial, optionally in collaboration with the dispatcher. (also comes from SLR-EXE-03) | G5: {=IF(A5="","",_xlfn.TEXTJOIN(", ",TRUE,_xlfn._xlws.FILTER(Objectives!B$2:B$1000,ISNUMBER(SEARCH(A5,Objectives!D$2:D$1000)),"")))}
E6: HLR-ATC-07 | F6: Air traffic control shall answer each flight crew request for a route, altitude or speed change with an approval, an amended clearance or 'unable'. | G6: {=IF(A6="","",_xlfn.TEXTJOIN(", ",TRUE,_xlfn._xlws.FILTER(Objectives!B$2:B$1000,ISNUMBER(SEARCH(A6,Objectives!D$2:D$1000)),"")))}
C7: SLR-EXE-03 | D7: The NAS shall predict each flight's arrival time, fuel at destination, optimum altitude and maximum altitude from the aircraft's estimated performance. (also answers SN-CRW-03) | E7: HLR-CRW-03 | F7: The flight crew shall ask air traffic control for a change of route, altitude or speed when the crew deems it beneficial, optionally in collaboration with the dispatcher. (also comes from SLR-CLR-09) | G7: {=IF(A7="","",_xlfn.TEXTJOIN(", ",TRUE,_xlfn._xlws.FILTER(Objectives!B$2:B$1000,ISNUMBER(SEARCH(A7,Objectives!D$2:D$1000)),"")))}
E8: HLR-CRW-05 | F8: The flight crew shall enter the load sheet weights and the released cost index into the flight management system before departure. (also comes from SLR-PLN-07) | G8: {=IF(A8="","",_xlfn.TEXTJOIN(", ",TRUE,_xlfn._xlws.FILTER(Objectives!B$2:B$1000,ISNUMBER(SEARCH(A8,Objectives!D$2:D$1000)),"")))}
E9: HLR-ACF-01 | F9: The flight management system shall predict the flight's arrival time, fuel at the destination, optimum altitude and maximum altitude from the entered weights, the cost index and the forecast winds. | G9: {=IF(A9="","",_xlfn.TEXTJOIN(", ",TRUE,_xlfn._xlws.FILTER(Objectives!B$2:B$1000,ISNUMBER(SEARCH(A9,Objectives!D$2:D$1000)),"")))}
E10: HLR-ACF-05 | F10: The flight management system shall make its current gross weight and its predicted optimum and maximum altitudes available for sharing with the party that decides, whether through the airline's systems or air traffic control's. (also comes from SLR-INF-02) | G10: {=IF(A10="","",_xlfn.TEXTJOIN(", ",TRUE,_xlfn._xlws.FILTER(Objectives!B$2:B$1000,ISNUMBER(SEARCH(A10,Objectives!D$2:D$1000)),"")))}
C11: SLR-MEA-02 | D11: The NAS shall report the fuel burned and the CO2 emitted by each flight, at 3.16 kg of CO2 per kg of fuel. (also answers SN-ENV-01) | E11: HLR-OPS-07 | F11: Flight operations shall report each flight's fuel burned and its CO2 emitted at 3.16 kg of CO2 per kg of fuel. | G11: {=IF(A11="","",_xlfn.TEXTJOIN(", ",TRUE,_xlfn._xlws.FILTER(Objectives!B$2:B$1000,ISNUMBER(SEARCH(A11,Objectives!D$2:D$1000)),"")))}
A12: SN-AIR-02 | B12: The NAS shall provide a means for each flight to achieve arrival at its destination gate at its scheduled arrival time. | C12: SLR-INF-07 | D12: The NAS shall send the airline and the destination airport an updated arrival estimate whenever a flight's estimate changes by more than 5 minutes. (also answers SN-AIR-03, SN-APT-01) | E12: HLR-CRW-04 | F12: The flight crew shall tell the dispatcher of each change to the cleared trajectory. (also comes from SLR-EXE-06, SLR-CLR-04) | G12: {=IF(A12="","",_xlfn.TEXTJOIN(", ",TRUE,_xlfn._xlws.FILTER(Objectives!B$2:B$1000,ISNUMBER(SEARCH(A12,Objectives!D$2:D$1000)),"")))} -> Aircraft utilization, Schedule integrity, Passenger connections, Dispatch reliability, Travel time, Connection reliability, Disruption risk, Predictability, Delay (ATC-attributed), Gate utilization, Runway utilization, Surface congestion, Turnaround performance, Passenger throughput, Schedule/duty constraints
E13: HLR-OPS-06 | F13: The dispatcher shall re-plan the flight with its crew when a trajectory change puts the arrival time, the fuel at the destination or flight safety at risk. (also comes from SLR-CLR-04, SLR-EXE-06) | G13: {=IF(A13="","",_xlfn.TEXTJOIN(", ",TRUE,_xlfn._xlws.FILTER(Objectives!B$2:B$1000,ISNUMBER(SEARCH(A13,Objectives!D$2:D$1000)),"")))}
C14: SLR-APT-01 | D14: [OUT OF STUDY] The NAS shall assign each arriving flight a gate before it lands. (also answers SN-APT-01) | F14: (no HLR: not carried into the study) | G14: {=IF(A14="","",_xlfn.TEXTJOIN(", ",TRUE,_xlfn._xlws.FILTER(Objectives!B$2:B$1000,ISNUMBER(SEARCH(A14,Objectives!D$2:D$1000)),"")))}
C15: SLR-APT-04 | D15: The NAS shall have each aircraft fuelled, loaded and sealed by its scheduled off- block time. | E15: HLR-APT-01 | F15: Airport operations shall have each aircraft fuelled, loaded and sealed by its scheduled off-block time. | G15: {=IF(A15="","",_xlfn.TEXTJOIN(", ",TRUE,_xlfn._xlws.FILTER(Objectives!B$2:B$1000,ISNUMBER(SEARCH(A15,Objectives!D$2:D$1000)),"")))}
E16: HLR-APT-02 | F16: Airport operations shall report the fuel uplifted and the load put on board to the flight crew and the load planner before off-block. (also comes from SLR-PLN-07) | G16: {=IF(A16="","",_xlfn.TEXTJOIN(", ",TRUE,_xlfn._xlws.FILTER(Objectives!B$2:B$1000,ISNUMBER(SEARCH(A16,Objectives!D$2:D$1000)),"")))}
C17: SLR-MEA-03 | D17: [OUT OF STUDY] The NAS shall report each flight's gate arrival time against its scheduled arrival time. (also answers SN-PAX-02) | F17: (no HLR: not carried into the study) | G17: {=IF(A17="","",_xlfn.TEXTJOIN(", ",TRUE,_xlfn._xlws.FILTER(Objectives!B$2:B$1000,ISNUMBER(SEARCH(A17,Objectives!D$2:D$1000)),"")))}
A18: SN-AIR-03 | B18: The NAS shall inform the airline of airspace and airport constraints that will delay or reroute its flights early enough for the airline to re-plan. | C18: SLR-FLW-07 | D18: [OUT OF STUDY] The NAS shall give traffic flow managers and airlines the activation schedule of special use airspace before the affected flight plans are filed. (also answers SN-MIL-01) | F18: (no HLR: not carried into the study) | G18: {=IF(A18="","",_xlfn.TEXTJOIN(", ",TRUE,_xlfn._xlws.FILTER(Objectives!B$2:B$1000,ISNUMBER(SEARCH(A18,Objectives!D$2:D$1000)),"")))} -> Schedule integrity, Delay cost
C19: SLR-CLR-04 | D19: The NAS shall provide a two-way communication path from the flight crew to the controlling facility and to the dispatcher for the whole flight. (also answers SN-CRW-08) | E19: HLR-CRW-04 | F19: The flight crew shall tell the dispatcher of each change to the cleared trajectory. (also comes from SLR-INF-07, SLR-EXE-06) | G19: {=IF(A19="","",_xlfn.TEXTJOIN(", ",TRUE,_xlfn._xlws.FILTER(Objectives!B$2:B$1000,ISNUMBER(SEARCH(A19,Objectives!D$2:D$1000)),"")))}
E20: HLR-OPS-06 | F20: The dispatcher shall re-plan the flight with its crew when a trajectory change puts the arrival time, the fuel at the destination or flight safety at risk. (also comes from SLR-INF-07, SLR-EXE-06) | G20: {=IF(A20="","",_xlfn.TEXTJOIN(", ",TRUE,_xlfn._xlws.FILTER(Objectives!B$2:B$1000,ISNUMBER(SEARCH(A20,Objectives!D$2:D$1000)),"")))}
E21: HLR-ACF-04 | F21: The aircraft communication system shall carry voice and data between the flight crew and both air traffic control and the dispatcher for the whole flight. | G21: {=IF(A21="","",_xlfn.TEXTJOIN(", ",TRUE,_xlfn._xlws.FILTER(Objectives!B$2:B$1000,ISNUMBER(SEARCH(A21,Objectives!D$2:D$1000)),"")))}
C22: SLR-INF-07 | D22: The NAS shall send the airline and the destination airport an updated arrival estimate whenever a flight's estimate changes by more than 5 minutes. (also answers SN-AIR-02, SN-APT-01) | E22: HLR-CRW-04 | F22: The flight crew shall tell the dispatcher of each change to the cleared trajectory. (also comes from SLR-EXE-06, SLR-CLR-04) | G22: {=IF(A22="","",_xlfn.TEXTJOIN(", ",TRUE,_xlfn._xlws.FILTER(Objectives!B$2:B$1000,ISNUMBER(SEARCH(A22,Objectives!D$2:D$1000)),"")))}
E23: HLR-OPS-06 | F23: The dispatcher shall re-plan the flight with its crew when a trajectory change puts the arrival time, the fuel at the destination or flight safety at risk. (also comes from SLR-CLR-04, SLR-EXE-06) | G23: {=IF(A23="","",_xlfn.TEXTJOIN(", ",TRUE,_xlfn._xlws.FILTER(Objectives!B$2:B$1000,ISNUMBER(SEARCH(A23,Objectives!D$2:D$1000)),"")))}
A24: SN-AIR-04 | B24: [OUT OF STUDY] The NAS shall let the airline choose which of its own flights takes a delay that the airline has been assigned. | C24: SLR-FLW-04 | D24: [OUT OF STUDY] The NAS shall let an airline exchange its own flights among the departure slots it has been assigned. | F24: (no HLR: not carried into the study) | G24: {=IF(A24="","",_xlfn.TEXTJOIN(", ",TRUE,_xlfn._xlws.FILTER(Objectives!B$2:B$1000,ISNUMBER(SEARCH(A24,Objectives!D$2:D$1000)),"")))}
A25: SN-AIR-05 | B25: The NAS shall take the airline's priorities for a flight (fuel against time, and protected connections) into account when a change to that flight's trajectory is required. | C25: SLR-CLR-13 | D25: [GOAL, IMPROVED] The NAS should choose, among the maneuvers that restore separation, the one with the lowest impact on the aircraft involved. (also answers SN-ENV-01) | E25: HLR-ATC-05 | F25: [GOAL, IMPROVED] Air traffic control should choose, among the clearances that resolve a conflict and can be flown, the one with the lowest impact on the systems involved. | G25: {=IF(A25="","",_xlfn.TEXTJOIN(", ",TRUE,_xlfn._xlws.FILTER(Objectives!B$2:B$1000,ISNUMBER(SEARCH(A25,Objectives!D$2:D$1000)),"")))} -> Fuel cost, Schedule integrity, Passenger connections, Operational flexibility, CO2, NOx, Contrail/climate effects, Noise, Local air quality
C26: SLR-INF-02 | D26: [IMPROVED] The NAS shall give the party that decides a change to an aircraft's trajectory the information needed to preserve safety and pursue optimality. (also answers SN-CRW-03) | E26: HLR-OPS-05 | F26: [IMPROVED] Flight operations shall make each flight's current gross weight, performance model, relative cost of flight time and connection priority available to the party that decides a change to that flight's trajectory. | G26: {=IF(A26="","",_xlfn.TEXTJOIN(", ",TRUE,_xlfn._xlws.FILTER(Objectives!B$2:B$1000,ISNUMBER(SEARCH(A26,Objectives!D$2:D$1000)),"")))}
E27: HLR-ATC-08 | F27: [IMPROVED] ATC decision support shall use the best information available to it about each flight, including the gross weight, performance model, relative cost of flight time and connection priority the airline has shared, to judge which clearances the aircraft can fly and what each costs. | G27: {=IF(A27="","",_xlfn.TEXTJOIN(", ",TRUE,_xlfn._xlws.FILTER(Objectives!B$2:B$1000,ISNUMBER(SEARCH(A27,Objectives!D$2:D$1000)),"")))}
E28: HLR-ACF-05 | F28: The flight management system shall make its current gross weight and its predicted optimum and maximum altitudes available for sharing with the party that decides, whether through the airline's systems or air traffic control's. (also comes from SLR-EXE-03) | G28: {=IF(A28="","",_xlfn.TEXTJOIN(", ",TRUE,_xlfn._xlws.FILTER(Objectives!B$2:B$1000,ISNUMBER(SEARCH(A28,Objectives!D$2:D$1000)),"")))}
A29: SN-AIR-06 | B29: [OUT OF STUDY] The NAS shall keep the airline's commercially sensitive flight data (aircraft weight, cost index, connection priorities) private. | C29: SLR-INF-05 | D29: [OUT OF STUDY] The NAS shall disclose an airline's shared weight, cost index and connection priority only to the parties deciding that flight's trajectory. | F29: (no HLR: not carried into the study) | G29: {=IF(A29="","",_xlfn.TEXTJOIN(", ",TRUE,_xlfn._xlws.FILTER(Objectives!B$2:B$1000,ISNUMBER(SEARCH(A29,Objectives!D$2:D$1000)),"")))}
A30: Stakeholder: Air traffic control | G30: {=IF(A30="","",_xlfn.TEXTJOIN(", ",TRUE,_xlfn._xlws.FILTER(Objectives!B$2:B$1000,ISNUMBER(SEARCH(A30,Objectives!D$2:D$1000)),"")))}
A31: SN-ATC-01 | B31: The NAS shall keep every controlled aircraft separated from every other aircraft by at least the applicable separation minimum. | C31: SLR-PLN-06 | D31: The NAS shall file each flight plan with air traffic control before the flight departs. (also answers SN-ATC-02, SN-ATC-03) | E31: HLR-OPS-02 | F31: The dispatcher shall file each flight's plan with air traffic control before departure. | G31: {=IF(A31="","",_xlfn.TEXTJOIN(", ",TRUE,_xlfn._xlws.FILTER(Objectives!B$2:B$1000,ISNUMBER(SEARCH(A31,Objectives!D$2:D$1000)),"")))} -> Flight Safety, Safety/separation
C32: SLR-CLR-01 | D32: The NAS shall keep each pair of controlled aircraft separated by at least the minimum that JO 7110.65BB sets for the airspace they are in. (also answers SN-CRW-06, SN-PAX-01) | E32: HLR-ATC-01 | F32: Air traffic control shall keep each pair of aircraft it controls separated by at least the applicable minimum, allowing for each aircraft's permitted deviation from its cleared route, altitude and speed. (also comes from SLR-EXE-02) | G32: {=IF(A32="","",_xlfn.TEXTJOIN(", ",TRUE,_xlfn._xlws.FILTER(Objectives!B$2:B$1000,ISNUMBER(SEARCH(A32,Objectives!D$2:D$1000)),"")))}
E33: HLR-ATC-04 | F33: [IMPROVED] Air traffic control shall resolve each predicted conflict with a clearance that every aircraft it moves can fly. (also comes from SLR-CLR-10) | G33: {=IF(A33="","",_xlfn.TEXTJOIN(", ",TRUE,_xlfn._xlws.FILTER(Objectives!B$2:B$1000,ISNUMBER(SEARCH(A33,Objectives!D$2:D$1000)),"")))}
E34: HLR-ACF-06 | F34: The aircraft's surveillance system shall broadcast the aircraft's position, altitude, velocity and identity by ADS-B Out. (also comes from SLR-CLR-02) | G34: {=IF(A34="","",_xlfn.TEXTJOIN(", ",TRUE,_xlfn._xlws.FILTER(Objectives!B$2:B$1000,ISNUMBER(SEARCH(A34,Objectives!D$2:D$1000)),"")))}
C35: SLR-CLR-02 | D35: The NAS shall predict a loss of separation between controlled aircraft before it occurs. (also answers SN-CRW-06) | E35: HLR-ATC-02 | F35: ATC decision support shall alert the sector controller to each predicted loss of separation before it occurs. | G35: {=IF(A35="","",_xlfn.TEXTJOIN(", ",TRUE,_xlfn._xlws.FILTER(Objectives!B$2:B$1000,ISNUMBER(SEARCH(A35,Objectives!D$2:D$1000)),"")))}
E36: HLR-ACF-06 | F36: The aircraft's surveillance system shall broadcast the aircraft's position, altitude, velocity and identity by ADS-B Out. (also comes from SLR-CLR-01) | G36: {=IF(A36="","",_xlfn.TEXTJOIN(", ",TRUE,_xlfn._xlws.FILTER(Objectives!B$2:B$1000,ISNUMBER(SEARCH(A36,Objectives!D$2:D$1000)),"")))}
C37: SLR-CLR-03 | D37: [OUT OF STUDY] The NAS shall give the controlling facility the position, altitude and identity of each controlled aircraft. (also answers SN-ATC-03) | F37: (no HLR: not carried into the study) | G37: {=IF(A37="","",_xlfn.TEXTJOIN(", ",TRUE,_xlfn._xlws.FILTER(Objectives!B$2:B$1000,ISNUMBER(SEARCH(A37,Objectives!D$2:D$1000)),"")))}
C38: SLR-CLR-05 | D38: [OUT OF STUDY] The NAS shall change a controlled aircraft's cleared route, altitude or speed only by a clearance from the facility that has control of that aircraft. (also answers SN-GOV-02) | F38: (no HLR: not carried into the study) | G38: {=IF(A38="","",_xlfn.TEXTJOIN(", ",TRUE,_xlfn._xlws.FILTER(Objectives!B$2:B$1000,ISNUMBER(SEARCH(A38,Objectives!D$2:D$1000)),"")))}
C39: SLR-INF-01 | D39: The NAS shall give the sector controller the filed route, requested altitude and requested speed of each aircraft before it enters the sector. (also answers SN-ATC-03) | E39: HLR-ATC-03 | F39: The en-route center shall inform the sector controller of each aircraft's filed route, requested altitude and requested speed before the aircraft enters the sector. | G39: {=IF(A39="","",_xlfn.TEXTJOIN(", ",TRUE,_xlfn._xlws.FILTER(Objectives!B$2:B$1000,ISNUMBER(SEARCH(A39,Objectives!D$2:D$1000)),"")))}
C40: SLR-EXE-02 | D40: The NAS shall fly each aircraft along its cleared route and at its cleared altitude and speed within the navigation and altitude tolerances of the airspace. (also answers SN-ATC-03) | E40: HLR-CRW-01 | F40: The flight crew shall safely control the flight from origin to destination, as cleared by air traffic control with or without negotiation, and in collaboration with flight operations. (also comes from SLR-CLR-08, SLR-PLN-05) | G40: {=IF(A40="","",_xlfn.TEXTJOIN(", ",TRUE,_xlfn._xlws.FILTER(Objectives!B$2:B$1000,ISNUMBER(SEARCH(A40,Objectives!D$2:D$1000)),"")))}
...

Sheet Coverage
A1: Check | B1: Count | C1: Which
A2: Stakeholder requirements in the study | B2: 11 | C2: SN-AIR-01, SN-AIR-02, SN-AIR-03, SN-AIR-05, SN-ATC-01, SN-ATC-02, SN-ATC-04, SN-CRW-03, SN-CRW-06, SN-CRW-07, SN-CRW-08
A3: Stakeholder requirements tagged background | B3: 2 | C3: SN-GOV-01, SN-ENV-01
A4: Stakeholder requirements out of the study | B4: 17 | C4: SN-AIR-04, SN-AIR-06, SN-ATC-03, SN-ATC-05, SN-CRW-01, SN-CRW-02, SN-CRW-04, SN-CRW-05, SN-GOV-02, SN-ENV-02, SN-APT-01, SN-APT-02, SN-APT-03, SN-PAX-01, SN-PAX-02, SN-PAX-03, SN-MIL-01
A5: System requirements in the study | B5: 23 | C5: SLR-PLN-01, SLR-PLN-02, SLR-PLN-04, SLR-PLN-05, SLR-PLN-06, SLR-PLN-07, SLR-CLR-01, SLR-CLR-02, SLR-CLR-04, SLR-CLR-08, SLR-CLR-09, SLR-CLR-10, SLR-CLR-13, SLR-CLR-15, SLR-INF-01, SLR-INF-02, SLR-INF-07, SLR-EXE-02, SLR-EXE-03, SLR-EXE-06, SLR-APT-04, SLR-MEA-01, SLR-MEA-02
A6: System requirements out of the study | B6: 19 | C6: SLR-PLN-08, SLR-PLN-09, SLR-FLW-04, SLR-FLW-05, SLR-FLW-06, SLR-FLW-07, SLR-CLR-03, SLR-CLR-05, SLR-CLR-14, SLR-INF-05, SLR-INF-06, SLR-EXE-01, SLR-EXE-04, SLR-APT-01, SLR-APT-02, SLR-APT-03, SLR-APT-05, SLR-MEA-03, SLR-MEA-04
A7: Sub-system HLRs | B7: 29 | C7: HLR-CRW-01, HLR-CRW-02, HLR-CRW-03, HLR-CRW-04, HLR-CRW-05, HLR-OPS-01, HLR-OPS-02, HLR-OPS-03, HLR-OPS-04, HLR-OPS-05, HLR-OPS-06, HLR-OPS-07, HLR-ATC-01, HLR-ATC-02, HLR-ATC-03, HLR-ATC-04, HLR-ATC-05, HLR-ATC-06, HLR-ATC-07, HLR-ATC-08, HLR-ATC-09, HLR-ACF-01, HLR-ACF-02, HLR-ACF-03, HLR-ACF-04, HLR-ACF-05, HLR-ACF-06, HLR-APT-01, HLR-APT-02
A8: GAP: stakeholder requirement with no system requirement | B8: 0
A9: GAP: system requirement with no stakeholder parent | B9: 0
A10: GAP: system requirement in the study with no HLR | B10: 0
A11: GAP: system requirement with no allocation | B11: 0
A12: GAP: HLR with no allocation | B12: 0
A13: CHECK: out-of-study system requirement that has an HLR | B13: 0
A14: CHECK: in-study system requirement whose only parents are out of study | B14: 0
A15: CHECK: HLR reached only through out-of-study system requirements | B15: 0

Sheet Objectives
A1: Category | B1: Objective row | C1: Trajectory impact | D1: Stakeholder requirements in the study | E1: Background / out of study | F1: In-study system requirements reached | G1: HLRs reached | H1: Review notes
A2: Airline | B2: Fuel cost | C2: Yes | D2: SN-AIR-01, SN-AIR-05 | F2: SLR-PLN-01, SLR-PLN-02, SLR-CLR-09, SLR-CLR-13, SLR-INF-02, SLR-EXE-03, SLR-MEA-02 | G2: HLR-CRW-03, HLR-CRW-05, HLR-OPS-01, HLR-OPS-05, HLR-OPS-07, HLR-ATC-05, HLR-ATC-07, HLR-ATC-08, HLR-ACF-01, HLR-ACF-05
A3: Airline | B3: Crew cost | C3: Indirect | D3: SN-AIR-01 | F3: SLR-PLN-01, SLR-PLN-02, SLR-CLR-09, SLR-EXE-03, SLR-MEA-02 | G3: HLR-CRW-03, HLR-CRW-05, HLR-OPS-01, HLR-OPS-07, HLR-ATC-07, HLR-ACF-01, HLR-ACF-05
A4: Airline | B4: Aircraft utilization | C4: Indirect | D4: SN-AIR-02 | F4: SLR-INF-07, SLR-APT-04 | G4: HLR-CRW-04, HLR-OPS-06, HLR-APT-01, HLR-APT-02
A5: Airline | B5: Maintenance | C5: Indirect | D5: SN-AIR-01 | F5: SLR-PLN-01, SLR-PLN-02, SLR-CLR-09, SLR-EXE-03, SLR-MEA-02 | G5: HLR-CRW-03, HLR-CRW-05, HLR-OPS-01, HLR-OPS-07, HLR-ATC-07, HLR-ACF-01, HLR-ACF-05
A6: Airline | B6: Schedule integrity | C6: Yes | D6: SN-AIR-02, SN-AIR-03, SN-AIR-05 | F6: SLR-CLR-04, SLR-CLR-13, SLR-INF-02, SLR-INF-07, SLR-APT-04 | G6: HLR-CRW-04, HLR-OPS-05, HLR-OPS-06, HLR-ATC-05, HLR-ATC-08, HLR-ACF-04, HLR-ACF-05, HLR-APT-01, HLR-APT-02
A7: Airline | B7: Passenger connections | C7: Yes | D7: SN-AIR-02, SN-AIR-05 | E7: SN-AIR-04 (out of study) | F7: SLR-CLR-13, SLR-INF-02, SLR-INF-07, SLR-APT-04 | G7: HLR-CRW-04, HLR-OPS-05, HLR-OPS-06, HLR-ATC-05, HLR-ATC-08, HLR-ACF-05, HLR-APT-01, HLR-APT-02
A8: Airline | B8: Delay cost | C8: Yes | D8: SN-AIR-01, SN-AIR-03 | E8: SN-AIR-04 (out of study) | F8: SLR-PLN-01, SLR-PLN-02, SLR-CLR-04, SLR-CLR-09, SLR-INF-07, SLR-EXE-03, SLR-MEA-02 | G8: HLR-CRW-03, HLR-CRW-04, HLR-CRW-05, HLR-OPS-01, HLR-OPS-06, HLR-OPS-07, HLR-ATC-07, HLR-ACF-01, HLR-ACF-04, HLR-ACF-05
A9: Airline | B9: Revenue | C9: Indirect | D9: SN-AIR-01 | F9: SLR-PLN-01, SLR-PLN-02, SLR-CLR-09, SLR-EXE-03, SLR-MEA-02 | G9: HLR-CRW-03, HLR-CRW-05, HLR-OPS-01, HLR-OPS-07, HLR-ATC-07, HLR-ACF-01, HLR-ACF-05
A10: Airline | B10: Dispatch reliability | C10: Indirect | D10: SN-AIR-02 | F10: SLR-INF-07, SLR-APT-04 | G10: HLR-CRW-04, HLR-OPS-06, HLR-APT-01, HLR-APT-02
A11: Airline | B11: Flight Safety | C11: Yes | D11: SN-ATC-01 | E11: SN-PAX-01 (out of study) | F11: SLR-PLN-06, SLR-CLR-01, SLR-CLR-02, SLR-INF-01, SLR-EXE-02 | G11: HLR-CRW-01, HLR-OPS-02, HLR-ATC-01, HLR-ATC-02, HLR-ATC-03, HLR-ATC-04, HLR-ACF-02, HLR-ACF-06
A12: Passenger | B12: Ticket price | C12: No | D12: SN-AIR-01 | F12: SLR-PLN-01, SLR-PLN-02, SLR-CLR-09, SLR-EXE-03, SLR-MEA-02 | G12: HLR-CRW-03, HLR-CRW-05, HLR-OPS-01, HLR-OPS-07, HLR-ATC-07, HLR-ACF-01, HLR-ACF-05
A13: Passenger | B13: Travel time | C13: Yes | D13: SN-AIR-02 | E13: SN-PAX-02 (out of study) | F13: SLR-INF-07, SLR-APT-04 | G13: HLR-CRW-04, HLR-OPS-06, HLR-APT-01, HLR-APT-02
A14: Passenger | B14: Connection reliability | C14: Yes | D14: SN-AIR-02 | E14: SN-PAX-02 (out of study) | F14: SLR-INF-07, SLR-APT-04 | G14: HLR-CRW-04, HLR-OPS-06, HLR-APT-01, HLR-APT-02
A15: Passenger | B15: Schedule convenience | C15: Indirect | D15: SN-AIR-01 | F15: SLR-PLN-01, SLR-PLN-02, SLR-CLR-09, SLR-EXE-03, SLR-MEA-02 | G15: HLR-CRW-03, HLR-CRW-05, HLR-OPS-01, HLR-OPS-07, HLR-ATC-07, HLR-ACF-01, HLR-ACF-05
A16: Passenger | B16: Comfort | C16: Yes | D16: SN-AIR-01 | E16: SN-PAX-03 (out of study) | F16: SLR-PLN-01, SLR-PLN-02, SLR-CLR-09, SLR-EXE-03, SLR-MEA-02 | G16: HLR-CRW-03, HLR-CRW-05, HLR-OPS-01, HLR-OPS-07, HLR-ATC-07, HLR-ACF-01, HLR-ACF-05
A17: Passenger | B17: Disruption risk | C17: Indirect | D17: SN-AIR-02 | E17: SN-PAX-02 (out of study) | F17: SLR-INF-07, SLR-APT-04 | G17: HLR-CRW-04, HLR-OPS-06, HLR-APT-01, HLR-APT-02
A18: ATC / ANSP | B18: Safety/separation | C18: Yes | D18: SN-ATC-01 | F18: SLR-PLN-06, SLR-CLR-01, SLR-CLR-02, SLR-INF-01, SLR-EXE-02 | G18: HLR-CRW-01, HLR-OPS-02, HLR-ATC-01, HLR-ATC-02, HLR-ATC-03, HLR-ATC-04, HLR-ACF-02, HLR-ACF-06
A19: ATC / ANSP | B19: Sector workload | C19: Yes | D19: SN-ATC-04 | F19: SLR-CLR-15 | G19: HLR-ATC-06
A20: ATC / ANSP | B20: Capacity | C20: Yes | D20: SN-ATC-02 | F20: SLR-PLN-06 | G20: HLR-OPS-02
A21: ATC / ANSP | B21: Predictability | C21: Yes | D21: SN-AIR-02 | E21: SN-ATC-03 (out of study) | F21: SLR-INF-07, SLR-APT-04 | G21: HLR-CRW-04, HLR-OPS-06, HLR-APT-01, HLR-APT-02
A22: ATC / ANSP | B22: Delay (ATC-attributed) | C22: Yes | D22: SN-AIR-02 | E22: SN-ATC-05 (out of study) | F22: SLR-INF-07, SLR-APT-04 | G22: HLR-CRW-04, HLR-OPS-06, HLR-APT-01, HLR-APT-02
A23: ATC / ANSP | B23: Traffic complexity | C23: Yes | D23: SN-ATC-04 | F23: SLR-CLR-15 | G23: HLR-ATC-06
A24: Airport | B24: Gate utilization | C24: Indirect | D24: SN-AIR-02 | E24: SN-APT-01 (out of study) | F24: SLR-INF-07, SLR-APT-04 | G24: HLR-CRW-04, HLR-OPS-06, HLR-APT-01, HLR-APT-02
A25: Airport | B25: Runway utilization | C25: Yes | D25: SN-AIR-02 | E25: SN-APT-02 (out of study) | F25: SLR-INF-07, SLR-APT-04 | G25: HLR-CRW-04, HLR-OPS-06, HLR-APT-01, HLR-APT-02
A26: Airport | B26: Surface congestion | C26: Yes | D26: SN-AIR-02 | E26: SN-APT-03 (out of study) | F26: SLR-INF-07, SLR-APT-04 | G26: HLR-CRW-04, HLR-OPS-06, HLR-APT-01, HLR-APT-02
A27: Airport | B27: Turnaround performance | C27: Indirect | D27: SN-AIR-02 | E27: SN-APT-01 (out of study) | F27: SLR-INF-07, SLR-APT-04 | G27: HLR-CRW-04, HLR-OPS-06, HLR-APT-01, HLR-APT-02
A28: Airport | B28: Passenger throughput | C28: No | D28: SN-AIR-02 | E28: SN-APT-01 (out of study) | F28: SLR-INF-07, SLR-APT-04 | G28: HLR-CRW-04, HLR-OPS-06, HLR-APT-01, HLR-APT-02
A29: Flight Crew | B29: Safety | C29: Yes | D29: SN-CRW-03, SN-CRW-06, SN-CRW-07 | E29: SN-CRW-01 (out of study), SN-CRW-02 (out of study) | F29: SLR-PLN-07, SLR-CLR-01, SLR-CLR-02, SLR-CLR-10, SLR-INF-02, SLR-EXE-03, SLR-EXE-06 | G29: HLR-CRW-02, HLR-CRW-03, HLR-CRW-04, HLR-CRW-05, HLR-OPS-03, HLR-OPS-05, HLR-OPS-06, HLR-ATC-01, HLR-ATC-02, HLR-ATC-04, HLR-ATC-08, HLR-ACF-01, HLR-ACF-03, HLR-ACF-05, HLR-ACF-06, HLR-APT-02
A30: Flight Crew | B30: Workload | C30: Yes | D30: SN-CRW-03, SN-CRW-08 | F30: SLR-CLR-04, SLR-CLR-10, SLR-INF-02, SLR-EXE-03, SLR-EXE-06 | G30: HLR-CRW-02, HLR-CRW-03, HLR-CRW-04, HLR-CRW-05, HLR-OPS-05, HLR-OPS-06, HLR-ATC-04, HLR-ATC-08, HLR-ACF-01, HLR-ACF-03, HLR-ACF-04, HLR-ACF-05
A31: Flight Crew | B31: Procedural compliance | C31: Yes | D31: SN-CRW-07, SN-CRW-08 | E31: SN-CRW-02 (out of study) | F31: SLR-PLN-07, SLR-CLR-04 | G31: HLR-CRW-04, HLR-CRW-05, HLR-OPS-03, HLR-OPS-06, HLR-ACF-04, HLR-APT-02
A32: Flight Crew | B32: Schedule/duty constraints | C32: Indirect | D32: SN-AIR-02 | E32: SN-CRW-05 (out of study) | F32: SLR-INF-07, SLR-APT-04 | G32: HLR-CRW-04, HLR-OPS-06, HLR-APT-01, HLR-APT-02
A33: Flight Crew | B33: Operational flexibility | C33: Yes | D33: SN-AIR-01, SN-AIR-05 | E33: SN-CRW-01 (out of study), SN-CRW-04 (out of study) | F33: SLR-PLN-01, SLR-PLN-02, SLR-CLR-09, SLR-CLR-13, SLR-INF-02, SLR-EXE-03, SLR-MEA-02 | G33: HLR-CRW-03, HLR-CRW-05, HLR-OPS-01, HLR-OPS-05, HLR-OPS-07, HLR-ATC-05, HLR-ATC-07, HLR-ATC-08, HLR-ACF-01, HLR-ACF-05
A34: Environmental / Societal | B34: CO2 | C34: Yes | D34: SN-AIR-01, SN-AIR-05 | E34: SN-ENV-01 (background) | F34: SLR-PLN-01, SLR-PLN-02, SLR-CLR-09, SLR-CLR-13, SLR-INF-02, SLR-EXE-03, SLR-MEA-02 | G34: HLR-CRW-03, HLR-CRW-05, HLR-OPS-01, HLR-OPS-05, HLR-OPS-07, HLR-ATC-05, HLR-ATC-07, HLR-ATC-08, HLR-ACF-01, HLR-ACF-05
A35: Environmental / Societal | B35: NOx | C35: Yes | D35: SN-AIR-01, SN-AIR-05 | E35: SN-ENV-01 (background) | F35: SLR-PLN-01, SLR-PLN-02, SLR-CLR-09, SLR-CLR-13, SLR-INF-02, SLR-EXE-03, SLR-MEA-02 | G35: HLR-CRW-03, HLR-CRW-05, HLR-OPS-01, HLR-OPS-05, HLR-OPS-07, HLR-ATC-05, HLR-ATC-07, HLR-ATC-08, HLR-ACF-01, HLR-ACF-05
A36: Environmental / Societal | B36: Contrail/climate effects | C36: Yes | D36: SN-AIR-01, SN-AIR-05 | E36: SN-ENV-01 (background) | F36: SLR-PLN-01, SLR-PLN-02, SLR-CLR-09, SLR-CLR-13, SLR-INF-02, SLR-EXE-03, SLR-MEA-02 | G36: HLR-CRW-03, HLR-CRW-05, HLR-OPS-01, HLR-OPS-05, HLR-OPS-07, HLR-ATC-05, HLR-ATC-07, HLR-ATC-08, HLR-ACF-01, HLR-ACF-05
A37: Environmental / Societal | B37: Noise | C37: Yes | D37: SN-AIR-01, SN-AIR-05 | E37: SN-ENV-02 (out of study) | F37: SLR-PLN-01, SLR-PLN-02, SLR-CLR-09, SLR-CLR-13, SLR-INF-02, SLR-EXE-03, SLR-MEA-02 | G37: HLR-CRW-03, HLR-CRW-05, HLR-OPS-01, HLR-OPS-05, HLR-OPS-07, HLR-ATC-05, HLR-ATC-07, HLR-ATC-08, HLR-ACF-01, HLR-ACF-05
A38: Environmental / Societal | B38: Local air quality | C38: Indirect | D38: SN-AIR-01, SN-AIR-05 | E38: SN-ENV-01 (background) | F38: SLR-PLN-01, SLR-PLN-02, SLR-CLR-09, SLR-CLR-13, SLR-INF-02, SLR-EXE-03, SLR-MEA-02 | G38: HLR-CRW-03, HLR-CRW-05, HLR-OPS-01, HLR-OPS-05, HLR-OPS-07, HLR-ATC-05, HLR-ATC-07, HLR-ATC-08, HLR-ACF-01, HLR-ACF-05
A39: Military | B39: Mission effectiveness | C39: Yes | E39: (no requirement)
A40: Military | B40: Mission timing | C40: Yes | E40: (no requirement)
...

Sheet Stakeholder reqs
A1: ID | B1: Group | C1: Requirement | D1: Objective rows | E1: Answered by | F1: Scope | G1: Status | H1: Basis | I1: Evidence | J1: Rationale (from the model) | K1: Review notes
A2: SN-AIR-01 | B2: Airline | C2: The NAS shall provide a means for the airline to plan and fly each flight on the route, altitude and speed it chooses. | D2: Airline: Fuel cost; Airline: Delay cost; Airline: Crew cost; Airline: Maintenance; Airline: Revenue; Passenger: Ticket price; Passenger: Schedule convenience; Passenger: Comfort; Flight Crew: Operational flexibility; Environmental / Societal: CO2; Environmental / Societal: NOx; Environmental / Societal: Contrail/climate effects; Environmental / Societal: Noise; Environmental / Societal: Local air quality | E2: SLR-PLN-01, SLR-PLN-02, SLR-CLR-09, SLR-EXE-03, SLR-MEA-02 | F2: inStudy | G2: draft | H2: [B] | I2: mori2022massCruise; munro2018managingVariability | J2: In the study: the planned cruise altitude and speed are what a conflict resolution takes the aircraft away from, so this is what the experiment scores a resolution against. The owner struck 'at its lowest operating cost' (hand review 2026-10-11): what the airline optimizes for is the airline's own business. The owner struck ', so that the flight is flown within safety and capacity limits' (hand review 2026-10-20). Objective rows added by the owner in the workbook review of 2026-10-22 (D-032): Airline: Crew cost; Airline: Maintenance; Airline: Revenue; Passenger: Ticket price; Passenger: Schedule convenience; Passenger: Comfort; Flight Crew: Operational flexibility; Environmental / Societal: CO2; Environmental / Societal: NOx; Environmental / Societal: Contrail/climate effects; Environmental / Societal: Noise; Environmental / Societal: Local air quality. Owner on 'Passenger: Ticket price' (2026-10-22): the airline sets prices from its costs, as represented in the fuel, time and maintenance impacts of its flight schedules as planned.
A3: SN-AIR-02 | B3: Airline | C3: The NAS shall provide a means for each flight to achieve arrival at its destination gate at its scheduled arrival time. | D3: Airline: Schedule integrity; Airline: Aircraft utilization; Airline: Passenger connections; Airline: Dispatch reliability; Passenger: Travel time; Passenger: Connection reliability; Passenger: Disruption risk; ATC / ANSP: Predictability; ATC / ANSP: Delay (ATC-attributed); Airport: Gate utilization; Airport: Runway utilization; Airport: Surface congestion; Airport: Turnaround performance; Airport: Passenger throughput; Flight Crew: Schedule/duty constraints | E3: SLR-INF-07, SLR-APT-01, SLR-APT-04, SLR-MEA-03 | F3: inStudy | G3: draft | H3: [C] | J3: In the study: the time side of the fuel-against-time trade, and the reason one flight's connections can outweigh its fuel (case D of the experiment). Owner's wording, hand review 2026-10-10. Objective rows added by the owner in the workbook review of 2026-10-22 (D-032): Airline: Dispatch reliability; Passenger: Travel time; Passenger: Connection reliability; Passenger: Disruption risk; ATC / ANSP: Predictability; ATC / ANSP: Delay (ATC-attributed); Airport: Gate utilization; Airport: Runway utilization; Airport: Surface congestion; Airport: Turnaround performance; Airport: Passenger throughput; Flight Crew: Schedule/duty constraints.
A4: SN-AIR-03 | B4: Airline | C4: The NAS shall inform the airline of airspace and airport constraints that will delay or reroute its flights early enough for the airline to re-plan. | D4: Airline: Delay cost; Airline: Schedule integrity | E4: SLR-FLW-07, SLR-CLR-04, SLR-INF-07 | F4: inStudy | G4: draft | H4: [A] | I4: faa2025jo72103ee | J4: In the study: flights are separated as filed; as uncertainty is realized, aircraft deviate and interventions are needed (owner, hand review 2026-10-11). The intervention is the constraint the airline needs to hear about, and the crew and the dispatchers are the ones who coordinate to make that happen (owner, 2026-10-11). Traffic management initiatives are outside the study (D-021).
A5: SN-AIR-04 | B5: Airline | C5: The NAS shall let the airline choose which of its own flights takes a delay that the airline has been assigned. | D5: Airline: Delay cost; Airline: Passenger connections | E5: SLR-FLW-04 | F5: outOfStudy | G5: draft | H5: [A] | I5: faa2025jo72103ee | J5: Restored as out of study (D-031): the owner's hand review of 2026-10-20 keeps every stakeholder requirement of the first draft and makes the cut at the sub-system (HLR) tier. Text as on the 2026-10-10 print. Struck 2026-10-10: 'This is about slot swapping... seems like it's only on strategic timelines, not tactical like I'm studying.' JO 7210.3EE 18-10-12 places it inside a ground delay program, before departure.
A6: SN-AIR-05 | B6: Airline | C6: The NAS shall take the airline's priorities for a flight (fuel against time, and protected connections) into account when a change to that flight's trajectory is required. | D6: Airline: Fuel cost; Airline: Schedule integrity; Airline: Passenger connections; Flight Crew: Operational flexibility; Environmental / Societal: CO2; Environmental / Societal: NOx; Environmental / Societal: Contrail/climate effects; Environmental / Societal: Noise; Environmental / Societal: Local air quality | E6: SLR-CLR-13, SLR-INF-02 | F6: inStudy | G6: draft | H6: [B] | I6: schultz2012adaptiveClimb; coppenbarger1999climbPrediction; kulkarni2019ctopSlotSubstitution | J6: In the study: this is the requirement the experiment is about (knowledge/models/experiment-definition.md section 2). Met today in part, before departure (owner, 2026-10-22): in the FAA's Collaborative Trajectory Options Program the airline submits a Trajectory Options Set, each route option carrying a Relative Trajectory Cost in equivalent ground-delay minutes, and the FAA's algorithm adds that cost to the assigned delay and picks the cheapest option (kulkarni2019ctopSlotSubstitution, p. 4). It is not met in tactical conflict resolution in cruise, the decision the study examines: the controller does not receive weight or cost index. Owner's wording, hand review 2026-10-10. Objective rows added by the owner in the workbook review of 2026-10-22 (D-032): Flight Crew: Operational flexibility; Environmental / Societal: CO2; Environmental / Societal: NOx; Environmental / Societal: Contrail/climate effects; Environmental / Societal: Noise; Environmental / Societal: Local air quality.
A7: SN-AIR-06 | B7: Airline | C7: The NAS shall keep the airline's commercially sensitive flight data (aircraft weight, cost index, connection priorities) private. | D7: none | E7: SLR-INF-05 | F7: outOfStudy | G7: draft | H7: [B] | I7: schultz2012adaptiveClimb | J7: Restored as out of study (D-031): the owner's hand review of 2026-10-20 keeps every stakeholder requirement of the first draft and makes the cut at the sub-system (HLR) tier. Text as on the 2026-10-10 print. Struck 2026-10-10: 'Important & real, but not pertinent to my project per D-007!' Carried as an assumption (D-020 item 4). No objective row matches it.
A8: SN-ATC-01 | B8: Air traffic control | C8: The NAS shall keep every controlled aircraft separated from every other aircraft by at least the applicable separation minimum. | D8: ATC / ANSP: Safety/separation; Airline: Flight Safety | E8: SLR-PLN-06, SLR-CLR-01, SLR-CLR-02, SLR-CLR-03, SLR-CLR-05, SLR-INF-01, SLR-EXE-02 | F8: inStudy | G8: draft | H8: [A] | I8: faa2025jo711065bb | J8: In the study: the hard constraint every resolution option must meet. It is never traded against cost (knowledge/models/experiment-definition.md section 6). Objective rows added by the owner in the workbook review of 2026-10-22 (D-032): Airline: Flight Safety.
A9: SN-ATC-02 | B9: Air traffic control | C9: The NAS shall keep the number of aircraft in each sector and at each airport within its declared capacity. | D9: ATC / ANSP: Capacity | E9: SLR-PLN-06, SLR-PLN-08, SLR-FLW-06, SLR-APT-02 | F9: inStudy | G9: draft | H9: [A] | I9: faa2025jo72103ee | J9: In the study: context. It is the capacity limit named in SN-AIR-01. Not marked in either hand review. The workload rows moved back to SN-ATC-04 (D-021).
A10: SN-ATC-03 | B10: Air traffic control | C10: The NAS shall make the path each controlled aircraft will fly known to its controller in advance. | D10: ATC / ANSP: Predictability | E10: SLR-PLN-06, SLR-FLW-06, SLR-CLR-03, SLR-INF-01, SLR-EXE-01, SLR-EXE-02 | F10: outOfStudy | G10: draft | H10: [B] | I10: coppenbarger1999climbPrediction | J10: Restored as out of study (D-031): the owner's hand review of 2026-10-20 keeps every stakeholder requirement of the first draft and makes the cut at the sub-system (HLR) tier. Text as on the 2026-10-10 print. Struck 2026-10-10: 'Not D-007'.
A11: SN-ATC-04 | B11: Air traffic control | C11: The NAS shall keep the number of control actions a sector controller must take within what one sector team can sustain. | D11: ATC / ANSP: Sector workload; ATC / ANSP: Traffic complexity | E11: SLR-CLR-15 | F11: inStudy | G11: draft | H11: [B] | I11: rantanen2012conflictManeuvers; kirwan2001coraStrategies | J11: Struck in the first hand review and brought back in the second (owner, 2026-10-11: 'Let's bring back SN-ATC-04'). In the study: instruction count is one of the experiment's two scored columns. Workload is a ceiling, not something to minimize: a controller who is not overworked can give as many instructions as wanted (owner, same review).
A12: SN-ATC-05 | B12: Air traffic control | C12: The NAS shall share unavoidable delay equitably among airspace users. | D12: ATC / ANSP: Delay (ATC-attributed) | E12: SLR-FLW-05, SLR-MEA-04 | F12: outOfStudy | G12: draft | H12: [A] | I12: faa2025jo72103ee | J12: Restored as out of study (D-031): the owner's hand review of 2026-10-20 keeps every stakeholder requirement of the first draft and makes the cut at the sub-system (HLR) tier. Text as on the 2026-10-10 print. Struck 2026-10-10 with no mark: its only system requirements were about traffic management initiatives.
A13: SN-CRW-01 | B13: Flight crew | C13: The NAS shall preserve the captain's final authority over the safe conduct of the flight. | D13: Flight Crew: Safety; Flight Crew: Operational flexibility | E13: SLR-PLN-05, SLR-CLR-08, SLR-EXE-04 | F13: outOfStudy | G13: draft | H13: [A] | I13: 14 CFR 91.3 | J13: Restored as out of study (D-031): the owner's hand review of 2026-10-20 keeps every stakeholder requirement of the first draft and makes the cut at the sub-system (HLR) tier. Text as on the 2026-10-10 print. Struck 2026-10-10 (crossed out).
A14: SN-CRW-02 | B14: Flight crew | C14: The NAS shall give the flight crew the information needed for each phase of flight before that phase begins. | D14: Flight Crew: Safety; Flight Crew: Procedural compliance | E14: SLR-PLN-01, SLR-PLN-07, SLR-INF-06, SLR-EXE-06 | F14: outOfStudy | G14: draft | H14: [B] | I14: seamster2011collabSystems | J14: Restored as out of study (D-031): the owner's hand review of 2026-10-20 keeps every stakeholder requirement of the first draft and makes the cut at the sub-system (HLR) tier. Text as on the 2026-10-10 print. Struck 2026-10-10 and replaced by the owner's SN-CRW-07.
A15: SN-CRW-03 | B15: Flight crew | C15: The NAS shall give the flight crew only trajectory clearances and instructions that the aircraft can fly, with enough time to set them up. | D15: Flight Crew: Workload; Flight Crew: Safety | E15: SLR-CLR-10, SLR-INF-02, SLR-EXE-03, SLR-EXE-06 | F15: inStudy | G15: draft | H15: [SME] | J15: In the study: a climb the aircraft is too heavy to make is the clearance the baseline can issue and the improved architecture avoids. The only flight crew requirement of the first draft the owner kept. 'Clearances and' added by the owner (hand review 2026-10-20).
A16: SN-CRW-04 | B16: Flight crew | C16: The NAS shall let the flight crew ask for a trajectory change and get an answer. | D16: Flight Crew: Operational flexibility | E16: SLR-CLR-09 | F16: outOfStudy | G16: draft | H16: [B] | I16: engility2014tasarAlaska | J16: Restored as out of study (D-031): the owner's hand review of 2026-10-20 keeps every stakeholder requirement of the first draft and makes the cut at the sub-system (HLR) tier. Text as on the 2026-10-10 print. Struck 2026-10-10 (crossed out).
A17: SN-CRW-05 | B17: Flight crew | C17: The NAS shall keep each flight crew member within flight and duty time limits. | D17: Flight Crew: Schedule/duty constraints | E17: SLR-PLN-09 | F17: outOfStudy | G17: draft | H17: [C] | I17: 14 CFR Part 117 | J17: Restored as out of study (D-031): the owner's hand review of 2026-10-20 keeps every stakeholder requirement of the first draft and makes the cut at the sub-system (HLR) tier. Text as on the 2026-10-10 print. Struck 2026-10-10: 'Not D-007'.
A18: SN-CRW-06 | B18: Flight crew | C18: The NAS shall provide the flight crew clearances that account for air traffic. | D18: Flight Crew: Safety | E18: SLR-CLR-01, SLR-CLR-02 | F18: inStudy | G18: draft | H18: [SME] | J18: Written by the owner in the hand review of 2026-10-10 (flight crew note 1). In the study: the clearance that resolves the conflict is the thing the crew receives. Objective row confirmed by the owner (hand review 2026-10-11).
A19: SN-CRW-07 | B19: Flight crew | C19: The NAS shall inform the flight crew of weather, traffic and other safety considerations. | D19: Flight Crew: Safety; Flight Crew: Procedural compliance | E19: SLR-PLN-07 | F19: inStudy | G19: draft | H19: [SME] | J19: Written by the owner in the hand review of 2026-10-10 (flight crew note 2). In the study: what the crew knows when it accepts, refuses or asks to change a clearance. On 2026-10-11 the owner replaced 'traffic management initiatives' with 'other safety considerations', as a catch-all. Objective rows confirmed by the owner (hand review 2026-10-11).
A20: SN-CRW-08 | B20: Flight crew | C20: The NAS shall facilitate control of the aircraft across regional sectors, coordinating controls, clearances and handoffs. | D20: Flight Crew: Workload; Flight Crew: Procedural compliance | E20: SLR-CLR-04 | F20: inStudy | G20: draft | H20: [SME] | J20: Written by the owner in the hand review of 2026-10-10 (flight crew note 3). In the study: the conflict is resolved by one sector controller, whose authority ends at the sector boundary. Objective rows confirmed by the owner (hand review 2026-10-11).
A21: SN-GOV-01 | B21: Regulator | C21: The NAS shall conduct every flight within the operating rules of 14 CFR and the FAA's air traffic orders. | D21: none | E21: SLR-PLN-04, SLR-PLN-05, SLR-PLN-09, SLR-CLR-08, SLR-EXE-06, SLR-MEA-01 | F21: background | G21: draft | H21: [A] | I21: faa2025jo711065bb; faa2025jo72103ee; 14 CFR 91; 14 CFR 121 | J21: In the study: the rules are held fixed (D-007), so both the baseline and the improved architecture must stay inside them. Governance has no table in knowledge/models/stakeholder-objective-ontology.md; the objective is 'Regulatory Compliance' in the enterprise objective hierarchy in knowledge/models/stakeholder-register.md. The owner judged adding a Governance table not important (hand review 2026-10-10). Owner (hand review 2026-10-20): 'How is this relevant via D-007? I think I need to remove.' Kept and tagged background (D-031): the regulator is a boundary actor whose rules are an input to the study, not a stakeholder whose objectives it weighs.
A22: SN-GOV-02 | B22: Regulator | C22: The NAS shall make one identified authority accountable for each decision that changes a flight's trajectory. | D22: none | E22: SLR-PLN-05, SLR-CLR-05, SLR-EXE-04, SLR-MEA-01 | F22: outOfStudy | G22: draft | H22: [A] | I22: 14 CFR 91.3; 14 CFR 121.533; faa2025jo711065bb | J22: Restored as out of study (D-031): the owner's hand review of 2026-10-20 keeps every stakeholder requirement of the first draft and makes the cut at the sub-system (HLR) tier. Text as on the 2026-10-10 print. Struck 2026-10-10: 'IDK about this one... the Note is an exception!' (the joint dispatcher and captain release). No objective row; from 'Regulatory Compliance' and 'Safety' in the enterprise objective hierarchy.
A23: SN-ENV-01 | B23: Communities and environment | C23: The NAS shall keep the CO2 emitted by each flight as low as safety, economics and capacity allow. | D23: Environmental / Societal: CO2; Environmental / Societal: NOx; Environmental / Societal: Contrail/climate effects; Environmental / Societal: Local air quality | E23: SLR-CLR-13, SLR-APT-03, SLR-MEA-02 | F23: background | G23: draft | H23: [C] | I23: icao2024icecMethodology | J23: In the study: CO2 is fuel burned times 3.16 (D-015), so the experiment's fuel column is also this stakeholder's column. 'Economics' was added by the owner (hand review 2026-10-10) and left standing in the second review. Owner (hand review 2026-10-20): 'This is currently in my cost, but not in my stakeholders. They're treated as background/input.' Tagged background (D-031). Objective rows added by the owner in the workbook review of 2026-10-22 (D-032): Environmental / Societal: NOx; Environmental / Societal: Contrail/climate effects; Environmental / Societal: Local air quality.
A24: SN-ENV-02 | B24: Communities and environment | C24: The NAS shall keep aircraft noise over communities near airports within the published noise abatement procedures. | D24: Environmental / Societal: Noise | E24: SLR-APT-05 | F24: outOfStudy | G24: draft | H24: [C] | J24: Restored as out of study (D-031): the owner's hand review of 2026-10-20 keeps every stakeholder requirement of the first draft and makes the cut at the sub-system (HLR) tier. Text as on the 2026-10-10 print. Struck 2026-10-10: 'Not important for cruise.'
A25: SN-APT-01 | B25: Airport operator | C25: The NAS shall give the airport operator arrival and departure times reliable enough to assign gates and ground crews. | D25: Airport: Gate utilization; Airport: Turnaround performance; Airport: Passenger throughput | E25: SLR-INF-07, SLR-APT-01 | F25: outOfStudy | G25: draft | H25: [C] | J25: Restored as out of study (D-031): the owner's hand review of 2026-10-20 keeps every stakeholder requirement of the first draft and makes the cut at the sub-system (HLR) tier. Text as on the 2026-10-10 print. Struck 2026-10-10: 'All of these are not D-007'. Objective rows added by the owner in the workbook review of 2026-10-22 (D-032): Airport: Passenger throughput.
A26: SN-APT-02 | B26: Airport operator | C26: The NAS shall use the runway capacity the airport has declared available. | D26: Airport: Runway utilization | E26: SLR-APT-02 | F26: outOfStudy | G26: draft | H26: [C] | J26: Restored as out of study (D-031): the owner's hand review of 2026-10-20 keeps every stakeholder requirement of the first draft and makes the cut at the sub-system (HLR) tier. Text as on the 2026-10-10 print. Struck 2026-10-10: 'All of these are not D-007'.
A27: SN-APT-03 | B27: Airport operator | C27: The NAS shall keep the time aircraft wait on taxiways with engines running as short as practical. | D27: Airport: Surface congestion | E27: SLR-APT-03 | F27: outOfStudy | G27: draft | H27: [C] | J27: Restored as out of study (D-031): the owner's hand review of 2026-10-20 keeps every stakeholder requirement of the first draft and makes the cut at the sub-system (HLR) tier. Text as on the 2026-10-10 print. Struck 2026-10-10: 'All of these are not D-007'.
A28: SN-PAX-01 | B28: Passengers | C28: The NAS shall carry passengers without injury. | D28: Airline: Flight Safety | E28: SLR-PLN-04, SLR-CLR-01, SLR-CLR-08, SLR-EXE-06 | F28: outOfStudy | G28: draft | H28: [C] | J28: Restored as out of study (D-031): the owner's hand review of 2026-10-20 keeps every stakeholder requirement of the first draft and makes the cut at the sub-system (HLR) tier. Text as on the 2026-10-10 print. Struck 2026-10-10: 'Not D-007'. The Passenger table in stakeholder-objective-ontology.md has no safety row; the interest comes from stakeholder-register.md (Social: Passengers, safety and convenience).
A29: SN-PAX-02 | B29: Passengers | C29: The NAS shall get passengers to their destination, including connections, at the time they were sold. | D29: Passenger: Travel time; Passenger: Connection reliability; Passenger: Disruption risk | E29: SLR-MEA-03 | F29: outOfStudy | G29: draft | H29: [C] | J29: Restored as out of study (D-031): the owner's hand review of 2026-10-20 keeps every stakeholder requirement of the first draft and makes the cut at the sub-system (HLR) tier. Text as on the 2026-10-10 print. Struck 2026-10-10: 'Not D-007'.
A30: SN-PAX-03 | B30: Passengers | C30: The NAS shall avoid known turbulence where a route or altitude change allows it. | D30: Passenger: Comfort | E30: SLR-CLR-09, SLR-INF-06 | F30: outOfStudy | G30: draft | H30: [C] | J30: Restored as out of study (D-031): the owner's hand review of 2026-10-20 keeps every stakeholder requirement of the first draft and makes the cut at the sub-system (HLR) tier. Text as on the 2026-10-10 print. Struck 2026-10-10: 'Not D-007'.
A31: SN-MIL-01 | B31: Military airspace users | C31: The NAS shall give military operations sole use of special use airspace while it is scheduled active. | D31: Military: Airspace access | E31: SLR-PLN-08, SLR-FLW-07, SLR-CLR-14 | F31: outOfStudy | G31: draft | H31: [C] | J31: Restored as out of study (D-031): the owner's hand review of 2026-10-20 keeps every stakeholder requirement of the first draft and makes the cut at the sub-system (HLR) tier. Text as on the 2026-10-10 print. Struck 2026-10-10 (crossed out). D-007 makes military operations a boundary actor.

Sheet System reqs
A1: ID | B1: Area | C1: Requirement | D1: Kind | E1: State | F1: Traces to | G1: Allocated to (accountable first) | H1: HLRs under it | I1: Check | J1: Measure | K1: Scope | L1: Status | M1: Basis | N1: Evidence | O1: Rationale (from the model) | P1: Review notes
A2: SLR-PLN-01 | B2: Flight planning and release | C2: The NAS shall produce for each scheduled flight a flight plan that states its route, cruise altitude, cruise speed and fuel load. | D2: Functional | E2: baseline | F2: SN-AIR-01, SN-CRW-02 | G2: Dispatcher | H2: HLR-OPS-01 | I2: Inspection | K2: inStudy | L2: draft | M2: [B] | N2: berry2011aocActors | O2: In the study: the flight plan sets the cruise altitude, speed and fuel load each aircraft has when the conflict occurs.
A3: SLR-PLN-02 | B3: Flight planning and release | C3: The NAS shall compute each flight plan from the performance of the aircraft assigned to the flight. | D3: Functional | E3: baseline | F3: SN-AIR-01 | G3: AOC decision support; Load planner | H3: HLR-OPS-01 | I3: Analysis | K3: inStudy | L3: draft | M3: [B] | N3: mori2022massCruise | O3: The owner struck 'the planned take-off weight' (hand review 2026-10-10). In the study: the cost-optimal altitude depends on mass (mori2022massCruise, Figure 1), which is why two aircraft of one type can want different levels. Owner (hand review 2026-10-11): the next tier can hold several requirements under this one, one per customer or way of computing it: low fidelity, high fidelity, and rules of thumb per aircraft type.
A4: SLR-PLN-04 | B4: Flight planning and release | C4: The NAS shall load each flight with fuel to reach its destination, then its most distant alternate, then fly 45 minutes at normal cruise. | D4: Constraint | E4: baseline | F4: SN-GOV-01, SN-PAX-01 | G4: Dispatcher | H4: HLR-OPS-01 | I4: Inspection | J4: fuel remaining after destination and alternate (minutes at normal cruise). Value: 45 | K4: inStudy | L4: draft | M4: [C] | N4: 14 CFR 121.639 | O4: The owner asked whether this is relevant for the weight assumptions. It is: the fuel load is part of the take-off weight, and the reserve sets the least fuel, and so the least weight, an aircraft can have in cruise. Owner (hand review 2026-10-11): it goes into the low-fidelity model's assumptions. Number and paragraph are from general knowledge; confirm against 14 CFR 121.639 before baselining.
A5: SLR-PLN-05 | B5: Flight planning and release | C5: The NAS shall release a flight only when the dispatcher and the captain both agree that it can be flown safely as planned. | D5: Functional | E5: baseline | F5: SN-GOV-01, SN-CRW-01, SN-GOV-02 | G5: Dispatcher; Flight deck crew | H5: HLR-CRW-01, HLR-OPS-04 | I5: Inspection | K5: inStudy | L5: draft | M5: [A] | N5: 14 CFR 121.533 | O5: Kept by the owner (hand review 2026-10-11). In the study: it is why a controller will issue a descent as a tactical change without negotiation and will not issue a climb. There is no question that a descent can be achieved. A climb is different: the released plan vouches for the planned level and nothing above it. That is the reasoning behind the rule of thumb (owner, 2026-10-11; 'DES' in the hand note is descent).
A6: SLR-PLN-06 | B6: Flight planning and release | C6: The NAS shall file each flight plan with air traffic control before the flight departs. | D6: Interface | E6: baseline | F6: SN-ATC-01, SN-ATC-02, SN-ATC-03 | G6: Dispatcher; Air traffic control | H6: HLR-OPS-02 | I6: Inspection | K6: inStudy | L6: draft | M6: [A] | N6: faa2025aim; faa2025jo72103ee | O6: In the study: the filed plan is the only statement of the airline's intent the controller has today, so it is the baseline that the proposed data share adds to. No lead time is set; the summary of faa2025aim records a 45 to 46 minute point before departure after which a filed plan is locked.
A7: SLR-PLN-07 | B7: Flight planning and release | C7: The NAS shall deliver the dispatch release, flight plan, weather, notices to airmen (NOTAMs) and load sheet to the flight crew before departure. | D7: Interface | E7: baseline | F7: SN-CRW-07, SN-CRW-02 | G7: Dispatcher; Load planner | H7: HLR-CRW-05, HLR-OPS-03, HLR-APT-02 | I7: Inspection | K7: inStudy | L7: draft | M7: [B] | N7: seamster2011collabSystems | O7: In the study: the load sheet is how the actual weight reaches the crew and the flight management system.
A8: SLR-PLN-08 | B8: Flight planning and release | C8: The NAS shall plan each flight to comply with the traffic management initiatives and special use airspace activations published for its time of flight. | D8: Constraint | E8: baseline | F8: SN-ATC-02, SN-MIL-01 | G8: Dispatcher; AOC ATC coordinator | I8: Inspection | K8: outOfStudy | L8: draft | M8: [A] | N8: faa2025jo72103ee | O8: Restored as out of study (D-031): the owner's hand review of 2026-10-20 keeps every stakeholder requirement of the first draft and makes the cut at the sub-system (HLR) tier. Text as on the 2026-10-10 print. Struck 2026-10-11 (crossed out): traffic management initiatives are not tactical interventions. It has no HLR: the study does not depend on it.
A9: SLR-PLN-09 | B9: Flight planning and release | C9: The NAS shall assign to each flight a crew whose duty period, including forecast delay, stays within the limits of 14 CFR Part 117. | D9: Constraint | E9: baseline | F9: SN-CRW-05, SN-GOV-01 | G9: Crew scheduler | I9: Inspection | K9: outOfStudy | L9: draft | M9: [C] | N9: 14 CFR Part 117 | O9: Restored as out of study (D-031): the owner's hand review of 2026-10-20 keeps every stakeholder requirement of the first draft and makes the cut at the sub-system (HLR) tier. Text as on the 2026-10-10 print. Struck 2026-10-10: 'Not important to project.' It has no HLR: the study does not depend on it.
A10: SLR-FLW-04 | B10: Traffic flow management | C10: The NAS shall let an airline exchange its own flights among the departure slots it has been assigned. | D10: Functional | E10: baseline | F10: SN-AIR-04 | G10: Command Center (ATCSCC); AOC ATC coordinator | I10: Demonstration | K10: outOfStudy | L10: draft | M10: [A] | N10: faa2025jo72103ee | O10: Restored as out of study (D-031): the owner's hand review of 2026-10-20 keeps every stakeholder requirement of the first draft and makes the cut at the sub-system (HLR) tier. Text as on the 2026-10-10 print. Struck 2026-10-10 with the whole traffic flow management section: 'TMIs aren't what I'm studying.' It has no HLR: the study does not depend on it.
A11: SLR-FLW-05 | B11: Traffic flow management | C11: The NAS shall assign the delay created by a traffic management initiative equitably among all airspace users. | D11: Performance | E11: baseline | F11: SN-ATC-05 | G11: Command Center (ATCSCC) | I11: Analysis | J11: assigned delay per flight, compared across airlines (minutes) | K11: outOfStudy | L11: draft | M11: [A] | N11: faa2025jo72103ee | O11: Restored as out of study (D-031): the owner's hand review of 2026-10-20 keeps every stakeholder requirement of the first draft and makes the cut at the sub-system (HLR) tier. Text as on the 2026-10-10 print. Struck 2026-10-10 with the whole traffic flow management section: 'TMIs aren't what I'm studying.' It has no HLR: the study does not depend on it.
A12: SLR-FLW-06 | B12: Traffic flow management | C12: The NAS shall release each flight that has an expect departure clearance time (EDCT) within the permitted window around that time. | D12: Performance | E12: baseline | F12: SN-ATC-02, SN-ATC-03 | G12: Control tower; Flight deck crew | I12: Analysis | J12: actual departure time minus EDCT (minutes) | K12: outOfStudy | L12: draft | M12: [C] | N12: faa2025jo72103ee | O12: Restored as out of study (D-031): the owner's hand review of 2026-10-20 keeps every stakeholder requirement of the first draft and makes the cut at the sub-system (HLR) tier. Text as on the 2026-10-10 print. Struck 2026-10-10 (crossed out). It has no HLR: the study does not depend on it.
A13: SLR-FLW-07 | B13: Traffic flow management | C13: The NAS shall give traffic flow managers and airlines the activation schedule of special use airspace before the affected flight plans are filed. | D13: Interface | E13: baseline | F13: SN-MIL-01, SN-AIR-03 | G13: Command Center (ATCSCC) | I13: Inspection | K13: outOfStudy | L13: draft | M13: [C] | O13: Restored as out of study (D-031): the owner's hand review of 2026-10-20 keeps every stakeholder requirement of the first draft and makes the cut at the sub-system (HLR) tier. Text as on the 2026-10-10 print. Struck 2026-10-10 (crossed out). It has no HLR: the study does not depend on it.
